Workbook

Sheet Старт
B1: BUSINESS SURGERY · Личный финансовый план | I1: =IF(Старт!$D$15="","",Старт!$D$15&" · ")&Старт!$D$16&" год" -> Ваше имя · 2026 год
B3: Старт
B4: Личный финансовый план предпринимателя: доходы, расходы, капитал и цели в одном файле
B7: 01 | C7: НАСТРОЙКИ
C8: Заполните белые ячейки. Остальное считается автоматически.
C9: Как читать ячейки
C10: Белая ячейка с рамкой: ваши данные, вводите и меняйте
C11: Серая ячейка: формула, считается сама
C12: Чёрная строка: итог, считается сам
B13: -1 | C13: Красный цвет: минус, превышение бюджета или риск
C15: Имя владельца плана | D15: Ваше имя | G15: Появится в шапке каждого листа
C16: Год плана | D16: 2026 | G16: Год, за который ведётся план
C17: Курс USD, ₸ за 1 $ | D17: 505 | G17: Для пересчёта валютных активов
C18: Цель: норма сбережений | D18: 0.25 | G18: Доля дохода, которую вы откладываете
C19: Цель: подушка безопасности, мес. | D19: 6 | G19: Сколько месяцев расходов держать в деньгах
C20: Лимит кредитной нагрузки | D20: 0.3 | G20: Платежи по кредитам к доходу, не больше
C21: Дата расчёта | D21: =TODAY() -> 46298 | G21: По умолчанию сегодня, можно ввести свою
C22: Месяцев с данными (авто) | D22: =MAX(1,COUNTIF(Расходы!$D$55:$O$55,">0")) -> 12 | G22: Считается по листу Расходы
B24: 02 | C24: КАК ПОЛЬЗОВАТЬСЯ: 5 ШАГОВ
B25: 01 | C25: Настройте план | D25: Впишите имя, год и курс доллара в блоке выше. Цели по сбережениям и подушке можно оставить по умолчанию.
B26: 02 | C26: Внесите доходы | D26: Лист Доходы: в колонке «План в мес» ваш ориентир, в месяцах фактические поступления по каждому источнику.
B27: 03 | C27: Ведите расходы | D27: Лист Расходы: задайте бюджет на месяц по каждой статье и раз в неделю вносите факт. Превышение подсветится красным.
B28: 04 | C28: Обновляйте капитал | D28: Лист Капитал: раз в месяц перепишите остатки на счетах, депозиты, акции в $, оценку бизнеса, имущество и долги.
B29: 05 | C29: Смотрите Дашборд | D29: Выберите месяц отчёта на Дашборде, проверьте цели на листе Цели и сверьтесь с Правилами. Итоги года на листе Год.
B31: Все цифры в файле являются примером, чтобы графики и показатели выглядели живыми. Замените примеры своими цифрами: перепишите значения в белых ячейках листов Доходы, Расходы, Капитал и Цели или выделите их и нажмите Delete. Формулы в серых и чёрных ячейках не трогайте.
B33: Совет: заведите привычку 15 минут в неделю. Факт расходов из банковских выписок, раз в месяц капитал, раз в квартал цели.
B35: © Business Surgery · bxclub.kz | I35: Шаблон для резидентов клуба

Sheet Дашборд
B1: BUSINESS SURGERY · Личный финансовый план | L1: =IF(Старт!$D$15="","",Старт!$D$15&" · ")&Старт!$D$16&" год" -> Ваше имя · 2026 год
B3: Дашборд
B4: Главные цифры месяца и года. Выберите месяц отчёта в белой ячейке
B6: Месяц отчёта | E6: Декабрь | G6: ="Месяцев с данными: "&Старт!$D$22 -> Месяцев с данными: 12
B8: ="МЕСЯЦ: "&UPPER(Дашборд!$E$6) -> МЕСЯЦ: ДЕКАБРЬ
B9: ДОХОД | E9: РАСХОД | H9: СБЕРЕЖЕНИЯ | K9: НОРМА СБЕРЕЖЕНИЙ
B10: =INDEX(Год!$C$8:$C$19,Год!$D$5) -> 4406000 | E10: =INDEX(Год!$E$8:$E$19,Год!$D$5) -> 2473000 | H10: =INDEX(Год!$H$8:$H$19,Год!$D$5) -> 1933000 | K10: =INDEX(Год!$I$8:$I$19,Год!$D$5) -> 0.43871993
B11: план | C11: =Доходы!$C$25 -> 3260000 | E11: бюджет | F11: =Расходы!$C$55 -> 2246000 | H11: к пред. месяцу | I11: =IF(Год!$D$5=1,0,INDEX(Год!$H$8:$H$19,Год!$D$5)-INDEX(Год!$H$8:$H$19,Год!$D$5-1)) -> 585000 | K11: цель | L11: =Старт!$D$18 -> 0.25
B13: ="С НАЧАЛА ГОДА ПО "&UPPER(Дашборд!$E$6) -> С НАЧАЛА ГОДА ПО ДЕКАБРЬ
B14: ДОХОД | E14: РАСХОД | H14: СБЕРЕЖЕНИЯ | K14: НОРМА СБЕРЕЖЕНИЙ
B15: =SUM(Год!$C$8:INDEX(Год!$C$8:$C$19,Год!$D$5)) -> 39759000 | E15: =SUM(Год!$E$8:INDEX(Год!$E$8:$E$19,Год!$D$5)) -> 26481000 | H15: =SUM(Год!$H$8:INDEX(Год!$H$8:$H$19,Год!$D$5)) -> 13278000 | K15: =IF(SUM(Год!$C$8:INDEX(Год!$C$8:$C$19,Год!$D$5))=0,0,SUM(Год!$H$8:INDEX(Год!$H$8:$H$19,Год!$D$5))/SUM(Год!$C$8:INDEX(Год!$C$8:$C$19,Год!$D$5))) -> 0.33396212
B16: в среднем в мес | C16: =SUM(Год!$C$8:INDEX(Год!$C$8:$C$19,Год!$D$5))/Год!$D$5 -> 3313250 | E16: к бюджету | F16: =SUM(Год!$G$8:INDEX(Год!$G$8:$G$19,Год!$D$5)) -> 471000 | H16: в среднем в мес | I16: =SUM(Год!$H$8:INDEX(Год!$H$8:$H$19,Год!$D$5))/Год!$D$5 -> 1106500 | K16: цель | L16: =Старт!$D$18 -> 0.25
B18: КАПИТАЛ И УСТОЙЧИВОСТЬ
B19: ЧИСТЫЙ КАПИТАЛ | E19: ФИНАНСОВАЯ ПОДУШКА | H19: ДОЛЯ БИЗНЕС-ДОХОДА | K19: КРЕДИТНАЯ НАГРУЗКА
B20: =INDEX(Год!$J$8:$J$19,Год!$D$5) -> 171255000 | E20: =IF(Год!$E$21=0,0,INDEX(Год!$L$8:$L$19,Год!$D$5)/Год!$E$21) -> 9.2171746 | H20: =IF(SUM(Год!$C$8:INDEX(Год!$C$8:$C$19,Год!$D$5))=0,0,SUM(Год!$D$8:INDEX(Год!$D$8:$D$19,Год!$D$5))/SUM(Год!$C$8:INDEX(Год!$C$8:$C$19,Год!$D$5))) -> 0.60527176 | K20: =IF(INDEX(Год!$C$8:$C$19,Год!$D$5)=0,0,INDEX(Расходы!$D$47:$O$47,Год!$D$5)/INDEX(Год!$C$8:$C$19,Год!$D$5)) -> 0.054471176
B21: рост с января | C21: =INDEX(Год!$J$8:$J$19,Год!$D$5)-Год!$J$8 -> 27956000 | E21: цель | F21: =Старт!$D$19 -> 6 | H21: с начала года | K21: лимит | L21: =Старт!$D$20 -> 0.3
B23: ПРОГРЕСС ЦЕЛЕЙ | E23: НУЖНО НА ЦЕЛИ В МЕС | H23: АКТИВЫ | K23: ДОЛГИ
B24: =Цели!$K$18 -> 0.1543011 | E24: =Цели!$J$18 -> 3269363.3 | H24: =INDEX(Капитал!$D$33:$O$33,Год!$D$5) -> 196035000 | K24: =INDEX(Капитал!$D$34:$O$34,Год!$D$5) -> 24780000
B25: накоплено | C25: =Цели!$G$18 -> 58440000 | E25: покрытие | F25: =IF(Цели!$J$18=0,0,Год!$H$21/Цели!$J$18) -> 0.33844511 | H25: из них деньги | I25: =INDEX(Год!$L$8:$L$19,Год!$D$5) -> 20340000 | K25: к активам | L25: =INDEX(Капитал!$D$38:$O$38,Год!$D$5) -> 0.126406
B28: ГРАФИКИ
B61: ЦЕЛИ
B62: Цель | H62: Прогресс | I62: Шкала | K62: Нужно в мес
B63: =IF(Цели!$C$8="","",Цели!$C$8) -> Финансовая подушка | H63: =Цели!$K$8 -> 1 | I63: =Цели!$L$8 -> ■■■■■■■■■■ | K63: =Цели!$J$8 -> 0
B64: =IF(Цели!$C$9="","",Цели!$C$9) -> Первый взнос за коммерческое помещение | H64: =Цели!$K$9 -> 0.34 | I64: =Цели!$L$9 -> ■■■□□□□□□□ | K64: =Цели!$J$9 -> 634615.38
B65: =IF(Цели!$C$10="","",Цели!$C$10) -> Образование детей | H65: =Цели!$K$10 -> 0.21333333 | I65: =Цели!$L$10 -> ■■□□□□□□□□ | K65: =Цели!$J$10 -> 168571.43
B66: =IF(Цели!$C$11="","",Цели!$C$11) -> Семейное путешествие | H66: =Цели!$K$11 -> 0.4 | I66: =Цели!$L$11 -> ■■■■□□□□□□ | K66: =Цели!$J$11 -> 262500
B67: =IF(Цели!$C$12="","",Цели!$C$12) -> Новый автомобиль | H67: =Цели!$K$12 -> 0.18181818 | I67: =Цели!$L$12 -> ■■□□□□□□□□ | K67: =Цели!$J$12 -> 562500
B68: =IF(Цели!$C$13="","",Цели!$C$13) -> Капитал на пассивный доход | H68: =Цели!$K$13 -> 0.07 | I68: =Цели!$L$13 -> ■□□□□□□□□□ | K68: =Цели!$J$13 -> 1641176.5
B70: © Business Surgery · bxclub.kz | L70: Шаблон для резидентов клуба

Sheet Доходы
B1: BUSINESS SURGERY · Личный финансовый план | R1: =IF(Старт!$D$15="","",Старт!$D$15&" · ")&Старт!$D$16&" год" -> Ваше имя · 2026 год
B3: Доходы
B4: Фактические поступления по месяцам. Белые ячейки ваши: переименуйте источники под себя
B7: Источник дохода | C7: План в мес | D7: Январь | E7: Февраль | F7: Март | G7: Апрель | H7: Май | I7: Июнь | J7: Июль | K7: Август | L7: Сентябрь | M7: Октябрь | N7: Ноябрь | O7: Декабрь | P7: Факт за год | Q7: Среднее в мес | R7: Доля
B8: БИЗНЕС-ДИВИДЕНДЫ | C8: =SUM(C9:C11) -> 1980000 | D8: =SUM(D9:D11) -> 1561000 | E8: =SUM(E9:E11) -> 1707000 | F8: =SUM(F9:F11) -> 1963000 | G8: =SUM(G9:G11) -> 1876000 | H8: =SUM(H9:H11) -> 2066000 | I8: =SUM(I9:I11) -> 2282000 | J8: =SUM(J9:J11) -> 1692000 | ... P8: =SUM(P9:P11) -> 24065000 | Q8: =P8/Старт!$D$22 -> 2005416.7 | R8: =IF($P$25=0,0,P8/$P$25) -> 0.60527176
B9: Компания 1 (основной бизнес) | C9: 1500000 | D9: 1182000 | E9: 1256000 | F9: 1524000 | G9: 1502000 | H9: 1597000 | I9: 1465000 | J9: 1256000 | K9: 1365000 | L9: 1590000 | M9: 1711000 | N9: 1655000 | O9: 2010000 | P9: =SUM(D9:O9) -> 18113000 | Q9: =P9/Старт!$D$22 -> 1509416.7 | R9: =IF($P$25=0,0,P9/$P$25) -> 0.45556981
B10: Компания 2 (доля партнёра) | C10: 400000 | D10: 379000 | E10: 451000 | F10: 439000 | G10: 374000 | H10: 469000 | I10: 467000 | J10: 436000 | K10: 432000 | L10: 385000 | M10: 371000 | N10: 423000 | O10: 376000 | P10: =SUM(D10:O10) -> 5002000 | Q10: =P10/Старт!$D$22 -> 416833.33 | R10: =IF($P$25=0,0,P10/$P$25) -> 0.12580799
B11: Проект 3 | C11: 80000 | D11: 0 | E11: 0 | F11: 0 | G11: 0 | H11: 0 | I11: 350000 | J11: 0 | K11: 0 | L11: 0 | M11: 0 | N11: 0 | O11: 600000 | P11: =SUM(D11:O11) -> 950000 | Q11: =P11/Старт!$D$22 -> 79166.667 | R11: =IF($P$25=0,0,P11/$P$25) -> 0.023893961
B12: ЗАРПЛАТА | C12: =SUM(C13:C14) -> 860000 | D12: =SUM(D13:D14) -> 800000 | E12: =SUM(E13:E14) -> 800000 | F12: =SUM(F13:F14) -> 1050000 | G12: =SUM(G13:G14) -> 800000 | H12: =SUM(H13:H14) -> 800000 | I12: =SUM(I13:I14) -> 800000 | J12: =SUM(J13:J14) -> 980000 | ... P12: =SUM(P13:P14) -> 10330000 | Q12: =P12/Старт!$D$22 -> 860833.33 | R12: =IF($P$25=0,0,P12/$P$25) -> 0.25981539
B13: Зарплата собственника | C13: 800000 | D13: 800000 | E13: 800000 | F13: 800000 | G13: 800000 | H13: 800000 | I13: 800000 | J13: 800000 | K13: 800000 | L13: 800000 | M13: 800000 | N13: 800000 | O13: 800000 | P13: =SUM(D13:O13) -> 9600000 | Q13: =P13/Старт!$D$22 -> 800000 | R13: =IF($P$25=0,0,P13/$P$25) -> 0.24145476
B14: Консалтинг, менторство, лекции | C14: 60000 | D14: 0 | E14: 0 | F14: 250000 | G14: 0 | H14: 0 | I14: 0 | J14: 180000 | K14: 0 | L14: 0 | M14: 300000 | N14: 0 | O14: 0 | P14: =SUM(D14:O14) -> 730000 | Q14: =P14/Старт!$D$22 -> 60833.333 | R14: =IF($P$25=0,0,P14/$P$25) -> 0.018360623
B15: ИНВЕСТИЦИИ И АКЦИИ | C15: =SUM(C16:C18) -> 140000 | D15: =SUM(D16:D18) -> 70000 | E15: =SUM(E16:E18) -> 74000 | F15: =SUM(F16:F18) -> 175000 | G15: =SUM(G16:G18) -> 84000 | H15: =SUM(H16:H18) -> 88000 | I15: =SUM(I16:I18) -> 291000 | J15: =SUM(J16:J18) -> 97000 | ... P15: =SUM(P16:P18) -> 1764000 | Q15: =P15/Старт!$D$22 -> 147000 | R15: =IF($P$25=0,0,P15/$P$25) -> 0.044367313
B16: Дивиденды по акциям и ETF | C16: 35000 | D16: 0 | E16: 0 | F16: 96000 | G16: 0 | H16: 0 | I16: 104000 | J16: 0 | K16: 0 | L16: 112000 | M16: 0 | N16: 0 | O16: 125000 | P16: =SUM(D16:O16) -> 437000 | Q16: =P16/Старт!$D$22 -> 36416.667 | R16: =IF($P$25=0,0,P16/$P$25) -> 0.010991222
B17: Проценты по депозитам | C17: 90000 | D17: 70000 | E17: 74000 | F17: 79000 | G17: 84000 | H17: 88000 | I17: 92000 | J17: 97000 | K17: 102000 | L17: 106000 | M17: 110000 | N17: 115000 | O17: 120000 | P17: =SUM(D17:O17) -> 1137000 | Q17: =P17/Старт!$D$22 -> 94750 | R17: =IF($P$25=0,0,P17/$P$25) -> 0.028597299
B18: Купоны по облигациям | C18: 15000 | D18: 0 | E18: 0 | F18: 0 | G18: 0 | H18: 0 | I18: 95000 | J18: 0 | K18: 0 | L18: 0 | M18: 0 | N18: 0 | O18: 95000 | P18: =SUM(D18:O18) -> 190000 | Q18: =P18/Старт!$D$22 -> 15833.333 | R18: =IF($P$25=0,0,P18/$P$25) -> 0.0047787922
B19: АРЕНДА | C19: =SUM(C20:C21) -> 280000 | D19: =SUM(D20:D21) -> 280000 | E19: =SUM(E20:E21) -> 280000 | F19: =SUM(F20:F21) -> 280000 | G19: =SUM(G20:G21) -> 280000 | H19: =SUM(H20:H21) -> 280000 | I19: =SUM(I20:I21) -> 280000 | J19: =SUM(J20:J21) -> 280000 | ... P19: =SUM(P20:P21) -> 3360000 | Q19: =P19/Старт!$D$22 -> 280000 | R19: =IF($P$25=0,0,P19/$P$25) -> 0.084509168
B20: Сдача квартиры | C20: 280000 | D20: 280000 | E20: 280000 | F20: 280000 | G20: 280000 | H20: 280000 | I20: 280000 | J20: 280000 | K20: 280000 | L20: 280000 | M20: 280000 | N20: 280000 | O20: 280000 | P20: =SUM(D20:O20) -> 3360000 | Q20: =P20/Старт!$D$22 -> 280000 | R20: =IF($P$25=0,0,P20/$P$25) -> 0.084509168
B21: Коммерческое помещение | C21: 0 | D21: 0 | E21: 0 | F21: 0 | G21: 0 | H21: 0 | I21: 0 | J21: 0 | K21: 0 | L21: 0 | M21: 0 | N21: 0 | O21: 0 | P21: =SUM(D21:O21) -> 0 | Q21: =P21/Старт!$D$22 -> 0 | R21: =IF($P$25=0,0,P21/$P$25) -> 0
B22: ПРОЧЕЕ | C22: =SUM(C23:C24) -> 0 | D22: =SUM(D23:D24) -> 50000 | E22: =SUM(E23:E24) -> 0 | F22: =SUM(F23:F24) -> 40000 | G22: =SUM(G23:G24) -> 150000 | H22: =SUM(H23:H24) -> 0 | I22: =SUM(I23:I24) -> 0 | J22: =SUM(J23:J24) -> 0 | ... P22: =SUM(P23:P24) -> 240000 | Q22: =P22/Старт!$D$22 -> 20000 | R22: =IF($P$25=0,0,P22/$P$25) -> 0.0060363691
B23: Продажа личных вещей | C23: 0 | D23: 0 | E23: 0 | F23: 0 | G23: 150000 | H23: 0 | I23: 0 | J23: 0 | K23: 0 | L23: 0 | M23: 0 | N23: 0 | O23: 0 | P23: =SUM(D23:O23) -> 150000 | Q23: =P23/Старт!$D$22 -> 12500 | R23: =IF($P$25=0,0,P23/$P$25) -> 0.0037727307
B24: Подарки и прочие поступления | C24: 0 | D24: 50000 | E24: 0 | F24: 40000 | G24: 0 | H24: 0 | I24: 0 | J24: 0 | K24: 0 | L24: 0 | M24: 0 | N24: 0 | O24: 0 | P24: =SUM(D24:O24) -> 90000 | Q24: =P24/Старт!$D$22 -> 7500 | R24: =IF($P$25=0,0,P24/$P$25) -> 0.0022636384
B25: ИТОГО ДОХОДЫ | C25: =C8+C12+C15+C19+C22 -> 3260000 | D25: =D8+D12+D15+D19+D22 -> 2761000 | E25: =E8+E12+E15+E19+E22 -> 2861000 | F25: =F8+F12+F15+F19+F22 -> 3508000 | G25: =G8+G12+G15+G19+G22 -> 3190000 | H25: =H8+H12+H15+H19+H22 -> 3234000 | I25: =I8+I12+I15+I19+I22 -> 3653000 | J25: =J8+J12+J15+J19+J22 -> 3049000 | ... P25: =P8+P12+P15+P19+P22 -> 39759000 | Q25: =P25/Старт!$D$22 -> 3313250 | R25: =IF($P$25=0,0,P25/$P$25) -> 1
B26: План месяца | D26: =$C$25 -> 3260000 | E26: =$C$25 -> 3260000 | F26: =$C$25 -> 3260000 | G26: =$C$25 -> 3260000 | H26: =$C$25 -> 3260000 | I26: =$C$25 -> 3260000 | J26: =$C$25 -> 3260000 | K26: =$C$25 -> 3260000 | ... O26: =$C$25 -> 3260000
B27: Отклонение: факт минус план | D27: =IF(D25=0,0,D25-D26) -> -499000 | E27: =IF(E25=0,0,E25-E26) -> -399000 | F27: =IF(F25=0,0,F25-F26) -> 248000 | G27: =IF(G25=0,0,G25-G26) -> -70000 | H27: =IF(H25=0,0,H25-H26) -> -26000 | I27: =IF(I25=0,0,I25-I26) -> 393000 | J27: =IF(J25=0,0,J25-J26) -> -211000 | K27: =IF(K25=0,0,K25-K26) -> -281000 | ... O27: =IF(O25=0,0,O25-O26) -> 1146000 | P27: =SUM(D27:O27) -> 639000
B29: Бизнес-дивиденды: только то, что вы реально вывели из бизнеса себе. Выручка и прибыль компании сюда не пишутся.
B30: Зарплата собственника: фиксированная выплата себе из бизнеса (см. Правила). Инвестиции: дивиденды, купоны, проценты по депозитам.
B31: Переименовать источник можно прямо в колонке B. Доля бизнес-дохода на Дашборде считается по группе «Бизнес-дивиденды».
B33: © Business Surgery · bxclub.kz | R33: Шаблон для резидентов клуба

Sheet Расходы
B1: BUSINESS SURGERY · Личный финансовый план | S1: =IF(Старт!$D$15="","",Старт!$D$15&" · ")&Старт!$D$16&" год" -> Ваше имя · 2026 год
B3: Расходы
B4: Бюджет на месяц и факт по месяцам. Отклонение считается за месяцы, в которых есть данные
B7: Статья расходов | C7: Бюджет в мес | D7: Январь | E7: Февраль | F7: Март | G7: Апрель | H7: Май | I7: Июнь | J7: Июль | K7: Август | L7: Сентябрь | M7: Октябрь | N7: Ноябрь | O7: Декабрь | P7: Факт за год | Q7: Бюджет за период | R7: Отклонение | S7: Исполнение
B8: ЖИЛЬЁ | C8: =SUM(C9:C12) -> 391000 | D8: =SUM(D9:D12) -> 375000 | E8: =SUM(E9:E12) -> 408000 | F8: =SUM(F9:F12) -> 365000 | G8: =SUM(G9:G12) -> 361000 | H8: =SUM(H9:H12) -> 534000 | I8: =SUM(I9:I12) -> 353000 | J8: =SUM(J9:J12) -> 352000 | ... P8: =SUM(P9:P12) -> 4622000 | Q8: =C8*Старт!$D$22 -> 4692000 | R8: =Q8-P8 -> 70000 | S8: =IF(Q8=0,0,P8/Q8) -> 0.98508099
B9: Ипотека или аренда | C9: 300000 | D9: 300000 | E9: 300000 | F9: 300000 | G9: 300000 | H9: 300000 | I9: 300000 | J9: 300000 | K9: 300000 | L9: 300000 | M9: 300000 | N9: 300000 | O9: 300000 | P9: =SUM(D9:O9) -> 3600000 | Q9: =C9*Старт!$D$22 -> 3600000 | R9: =Q9-P9 -> 0 | S9: =IF(Q9=0,0,P9/Q9) -> 1
B10: Коммунальные платежи | C10: 50000 | D10: 59000 | E10: 57000 | F10: 49000 | G10: 45000 | H10: 38000 | I10: 37000 | J10: 36000 | K10: 37000 | L10: 38000 | M10: 46000 | N10: 54000 | O10: 59000 | P10: =SUM(D10:O10) -> 555000 | Q10: =C10*Старт!$D$22 -> 600000 | R10: =Q10-P10 -> 45000 | S10: =IF(Q10=0,0,P10/Q10) -> 0.925
B11: Интернет и мобильная связь | C11: 16000 | D11: 16000 | E11: 16000 | F11: 16000 | G11: 16000 | H11: 16000 | I11: 16000 | J11: 16000 | K11: 16000 | L11: 16000 | M11: 16000 | N11: 16000 | O11: 16000 | P11: =SUM(D11:O11) -> 192000 | Q11: =C11*Старт!$D$22 -> 192000 | R11: =Q11-P11 -> 0 | S11: =IF(Q11=0,0,P11/Q11) -> 1
B12: Ремонт и обслуживание | C12: 25000 | D12: 0 | E12: 35000 | F12: 0 | G12: 0 | H12: 180000 | I12: 0 | J12: 0 | K12: 0 | L12: 60000 | M12: 0 | N12: 0 | O12: 0 | P12: =SUM(D12:O12) -> 275000 | Q12: =C12*Старт!$D$22 -> 300000 | R12: =Q12-P12 -> 25000 | S12: =IF(Q12=0,0,P12/Q12) -> 0.91666667
B13: ЕДА | C13: =SUM(C14:C16) -> 335000 | D13: =SUM(D14:D16) -> 358000 | E13: =SUM(E14:E16) -> 358000 | F13: =SUM(F14:F16) -> 329000 | G13: =SUM(G14:G16) -> 330000 | H13: =SUM(H14:H16) -> 339000 | I13: =SUM(I14:I16) -> 320000 | J13: =SUM(J14:J16) -> 341000 | ... P13: =SUM(P14:P16) -> 4015000 | Q13: =C13*Старт!$D$22 -> 4020000 | R13: =Q13-P13 -> 5000 | S13: =IF(Q13=0,0,P13/Q13) -> 0.99875622
B14: Продукты | C14: 190000 | D14: 198000 | E14: 198000 | F14: 194000 | G14: 190000 | H14: 180000 | I14: 178000 | J14: 180000 | K14: 174000 | L14: 192000 | M14: 182000 | N14: 194000 | O14: 182000 | P14: =SUM(D14:O14) -> 2242000 | Q14: =C14*Старт!$D$22 -> 2280000 | R14: =Q14-P14 -> 38000 | S14: =IF(Q14=0,0,P14/Q14) -> 0.98333333
B15: Кафе и рестораны | C15: 110000 | D15: 130000 | E15: 125000 | F15: 88000 | G15: 97000 | H15: 128000 | I15: 109000 | J15: 131000 | K15: 105000 | L15: 91000 | M15: 116000 | N15: 122000 | O15: 100000 | P15: =SUM(D15:O15) -> 1342000 | Q15: =C15*Старт!$D$22 -> 1320000 | R15: =Q15-P15 -> -22000 | S15: =IF(Q15=0,0,P15/Q15) -> 1.0166667
B16: Доставка еды | C16: 35000 | D16: 30000 | E16: 35000 | F16: 47000 | G16: 43000 | H16: 31000 | I16: 33000 | J16: 30000 | K16: 30000 | L16: 44000 | M16: 32000 | N16: 39000 | O16: 37000 | P16: =SUM(D16:O16) -> 431000 | Q16: =C16*Старт!$D$22 -> 420000 | R16: =Q16-P16 -> -11000 | S16: =IF(Q16=0,0,P16/Q16) -> 1.0261905
B17: СЕМЬЯ И ДЕТИ | C17: =SUM(C18:C21) -> 335000 | D17: =SUM(D18:D21) -> 333000 | E17: =SUM(E18:E21) -> 337000 | F17: =SUM(F18:F21) -> 332000 | G17: =SUM(G18:G21) -> 336000 | H17: =SUM(H18:H21) -> 332000 | I17: =SUM(I18:I21) -> 334000 | J17: =SUM(J18:J21) -> 148000 | ... P17: =SUM(P18:P21) -> 3648000 | Q17: =C17*Старт!$D$22 -> 4020000 | R17: =Q17-P17 -> 372000 | S17: =IF(Q17=0,0,P17/Q17) -> 0.90746269
B18: Детский сад, школа | C18: 150000 | D18: 150000 | E18: 150000 | F18: 150000 | G18: 150000 | H18: 150000 | I18: 150000 | J18: 0 | K18: 0 | L18: 150000 | M18: 150000 | N18: 150000 | O18: 150000 | P18: =SUM(D18:O18) -> 1500000 | Q18: =C18*Старт!$D$22 -> 1800000 | R18: =Q18-P18 -> 300000 | S18: =IF(Q18=0,0,P18/Q18) -> 0.83333333
B19: Кружки и секции | C19: 60000 | D19: 60000 | E19: 60000 | F19: 60000 | G19: 60000 | H19: 60000 | I19: 60000 | J19: 25000 | K19: 25000 | L19: 60000 | M19: 60000 | N19: 60000 | O19: 60000 | P19: =SUM(D19:O19) -> 650000 | Q19: =C19*Старт!$D$22 -> 720000 | R19: =Q19-P19 -> 70000 | S19: =IF(Q19=0,0,P19/Q19) -> 0.90277778
B20: Помощь родителям | C20: 100000 | D20: 100000 | E20: 100000 | F20: 100000 | G20: 100000 | H20: 100000 | I20: 100000 | J20: 100000 | K20: 100000 | L20: 100000 | M20: 100000 | N20: 100000 | O20: 100000 | P20: =SUM(D20:O20) -> 1200000 | Q20: =C20*Старт!$D$22 -> 1200000 | R20: =Q20-P20 -> 0 | S20: =IF(Q20=0,0,P20/Q20) -> 1
B21: Хозяйственные товары | C21: 25000 | D21: 23000 | E21: 27000 | F21: 22000 | G21: 26000 | H21: 22000 | I21: 24000 | J21: 23000 | K21: 23000 | L21: 29000 | M21: 27000 | N21: 24000 | O21: 28000 | P21: =SUM(D21:O21) -> 298000 | Q21: =C21*Старт!$D$22 -> 300000 | R21: =Q21-P21 -> 2000 | S21: =IF(Q21=0,0,P21/Q21) -> 0.99333333
B22: ТРАНСПОРТ | C22: =SUM(C23:C26) -> 103000 | D22: =SUM(D23:D26) -> 86000 | E22: =SUM(E23:E26) -> 93000 | F22: =SUM(F23:F26) -> 90000 | G22: =SUM(G23:G26) -> 223000 | H22: =SUM(H23:H26) -> 87000 | I22: =SUM(I23:I26) -> 98000 | J22: =SUM(J23:J26) -> 92000 | ... P22: =SUM(P23:P26) -> 1303000 | Q22: =C22*Старт!$D$22 -> 1236000 | R22: =Q22-P22 -> -67000 | S22: =IF(Q22=0,0,P22/Q22) -> 1.0542071
B23: Бензин | C23: 50000 | D23: 49000 | E23: 51000 | F23: 56000 | G23: 53000 | H23: 48000 | I23: 57000 | J23: 49000 | K23: 49000 | L23: 55000 | M23: 50000 | N23: 50000 | O23: 48000 | P23: =SUM(D23:O23) -> 615000 | Q23: =C23*Старт!$D$22 -> 600000 | R23: =Q23-P23 -> -15000 | S23: =IF(Q23=0,0,P23/Q23) -> 1.025
B24: Обслуживание авто | C24: 25000 | D24: 8000 | E24: 8000 | F24: 8000 | G24: 140000 | H24: 8000 | I24: 8000 | J24: 8000 | K24: 8000 | L24: 8000 | M24: 95000 | N24: 8000 | O24: 8000 | P24: =SUM(D24:O24) -> 315000 | Q24: =C24*Старт!$D$22 -> 300000 | R24: =Q24-P24 -> -15000 | S24: =IF(Q24=0,0,P24/Q24) -> 1.05
B25: Такси | C25: 20000 | D25: 17000 | E25: 23000 | F25: 19000 | G25: 23000 | H25: 20000 | I25: 21000 | J25: 28000 | K25: 22000 | L25: 23000 | M25: 27000 | N25: 18000 | O25: 17000 | P25: =SUM(D25:O25) -> 258000 | Q25: =C25*Старт!$D$22 -> 240000 | R25: =Q25-P25 -> -18000 | S25: =IF(Q25=0,0,P25/Q25) -> 1.075
B26: Парковка и штрафы | C26: 8000 | D26: 12000 | E26: 11000 | F26: 7000 | G26: 7000 | H26: 11000 | I26: 12000 | J26: 7000 | K26: 12000 | L26: 12000 | M26: 10000 | N26: 8000 | O26: 6000 | P26: =SUM(D26:O26) -> 115000 | Q26: =C26*Старт!$D$22 -> 96000 | R26: =Q26-P26 -> -19000 | S26: =IF(Q26=0,0,P26/Q26) -> 1.1979167
B27: ЗДОРОВЬЕ И СПОРТ | C27: =SUM(C28:C31) -> 125000 | D27: =SUM(D28:D31) -> 327000 | E27: =SUM(E28:E31) -> 118000 | F27: =SUM(F28:F31) -> 93000 | G27: =SUM(G28:G31) -> 103000 | H27: =SUM(H28:H31) -> 98000 | I27: =SUM(I28:I31) -> 106000 | J27: =SUM(J28:J31) -> 97000 | ... P27: =SUM(P28:P31) -> 1397000 | Q27: =C27*Старт!$D$22 -> 1500000 | R27: =Q27-P27 -> 103000 | S27: =IF(Q27=0,0,P27/Q27) -> 0.93133333
B28: Спортзал, тренер | C28: 45000 | D28: 45000 | E28: 45000 | F28: 45000 | G28: 45000 | H28: 45000 | I28: 45000 | J28: 45000 | K28: 45000 | L28: 45000 | M28: 45000 | N28: 45000 | O28: 45000 | P28: =SUM(D28:O28) -> 540000 | Q28: =C28*Старт!$D$22 -> 540000 | R28: =Q28-P28 -> 0 | S28: =IF(Q28=0,0,P28/Q28) -> 1
B29: Медицина и лекарства | C29: 30000 | D29: 11000 | E29: 39000 | F29: 17000 | G29: 31000 | H29: 18000 | I29: 35000 | J29: 28000 | K29: 19000 | L29: 15000 | M29: 32000 | N29: 12000 | O29: 17000 | P29: =SUM(D29:O29) -> 274000 | Q29: =C29*Старт!$D$22 -> 360000 | R29: =Q29-P29 -> 86000 | S29: =IF(Q29=0,0,P29/Q29) -> 0.76111111
B30: Медицинская страховка | C30: 20000 | D30: 240000 | E30: 0 | F30: 0 | G30: 0 | H30: 0 | I30: 0 | J30: 0 | K30: 0 | L30: 0 | M30: 0 | N30: 0 | O30: 0 | P30: =SUM(D30:O30) -> 240000 | Q30: =C30*Старт!$D$22 -> 240000 | R30: =Q30-P30 -> 0 | S30: =IF(Q30=0,0,P30/Q30) -> 1
B31: Уход за собой | C31: 30000 | D31: 31000 | E31: 34000 | F31: 31000 | G31: 27000 | H31: 35000 | I31: 26000 | J31: 24000 | K31: 27000 | L31: 29000 | M31: 25000 | N31: 26000 | O31: 28000 | P31: =SUM(D31:O31) -> 343000 | Q31: =C31*Старт!$D$22 -> 360000 | R31: =Q31-P31 -> 17000 | S31: =IF(Q31=0,0,P31/Q31) -> 0.95277778
B32: ОДЕЖДА | C32: =SUM(C33:C34) -> 82000 | D32: =SUM(D33:D34) -> 56000 | E32: =SUM(E33:E34) -> 51000 | F32: =SUM(F33:F34) -> 169000 | G32: =SUM(G33:G34) -> 59000 | H32: =SUM(H33:H34) -> 60000 | I32: =SUM(I33:I34) -> 57000 | J32: =SUM(J33:J34) -> 57000 | ... P32: =SUM(P33:P34) -> 1035000 | Q32: =C32*Старт!$D$22 -> 984000 | R32: =Q32-P32 -> -51000 | S32: =IF(Q32=0,0,P32/Q32) -> 1.0518293
B33: Одежда и обувь | C33: 70000 | D33: 45000 | E33: 45000 | F33: 160000 | G33: 45000 | H33: 45000 | I33: 45000 | J33: 45000 | K33: 45000 | L33: 210000 | M33: 45000 | N33: 140000 | O33: 45000 | P33: =SUM(D33:O33) -> 915000 | Q33: =C33*Старт!$D$22 -> 840000 | R33: =Q33-P33 -> -75000 | S33: =IF(Q33=0,0,P33/Q33) -> 1.0892857
B34: Аксессуары | C34: 12000 | D34: 11000 | E34: 6000 | F34: 9000 | G34: 14000 | H34: 15000 | I34: 12000 | J34: 12000 | K34: 11000 | L34: 6000 | M34: 5000 | N34: 5000 | O34: 14000 | P34: =SUM(D34:O34) -> 120000 | Q34: =C34*Старт!$D$22 -> 144000 | R34: =Q34-P34 -> 24000 | S34: =IF(Q34=0,0,P34/Q34) -> 0.83333333
B35: ОБРАЗОВАНИЕ | C35: =SUM(C36:C38) -> 147000 | D35: =SUM(D36:D38) -> 102000 | E35: =SUM(E36:E38) -> 282000 | F35: =SUM(F36:F38) -> 102000 | G35: =SUM(G36:G38) -> 102000 | H35: =SUM(H36:H38) -> 102000 | I35: =SUM(I36:I38) -> 102000 | J35: =SUM(J36:J38) -> 102000 | ... P35: =SUM(P36:P38) -> 1754000 | Q35: =C35*Старт!$D$22 -> 1764000 | R35: =Q35-P35 -> 10000 | S35: =IF(Q35=0,0,P35/Q35) -> 0.99433107
B36: Курсы и тренинги | C36: 45000 | D36: 0 | E36: 180000 | F36: 0 | G36: 0 | H36: 0 | I36: 0 | J36: 0 | K36: 0 | L36: 350000 | M36: 0 | N36: 0 | O36: 0 | P36: =SUM(D36:O36) -> 530000 | Q36: =C36*Старт!$D$22 -> 540000 | R36: =Q36-P36 -> 10000 | S36: =IF(Q36=0,0,P36/Q36) -> 0.98148148
B37: Книги и подписки | C37: 12000 | D37: 12000 | E37: 12000 | F37: 12000 | G37: 12000 | H37: 12000 | I37: 12000 | J37: 12000 | K37: 12000 | L37: 12000 | M37: 12000 | N37: 12000 | O37: 12000 | P37: =SUM(D37:O37) -> 144000 | Q37: =C37*Старт!$D$22 -> 144000 | R37: =Q37-P37 -> 0 | S37: =IF(Q37=0,0,P37/Q37) -> 1
B38: Бизнес-клуб и нетворкинг | C38: 90000 | D38: 90000 | E38: 90000 | F38: 90000 | G38: 90000 | H38: 90000 | I38: 90000 | J38: 90000 | K38: 90000 | L38: 90000 | M38: 90000 | N38: 90000 | O38: 90000 | P38: =SUM(D38:O38) -> 1080000 | Q38: =C38*Старт!$D$22 -> 1080000 | R38: =Q38-P38 -> 0 | S38: =IF(Q38=0,0,P38/Q38) -> 1
B39: ОТДЫХ | C39: =SUM(C40:C42) -> 255000 | D39: =SUM(D40:D42) -> 74000 | E39: =SUM(E40:E42) -> 79000 | F39: =SUM(F40:F42) -> 708000 | G39: =SUM(G40:G42) -> 74000 | H39: =SUM(H40:H42) -> 63000 | I39: =SUM(I40:I42) -> 74000 | J39: =SUM(J40:J42) -> 1167000 | ... P39: =SUM(P40:P42) -> 3048000 | Q39: =C39*Старт!$D$22 -> 3060000 | R39: =Q39-P39 -> 12000 | S39: =IF(Q39=0,0,P39/Q39) -> 0.99607843
B40: Путешествия | C40: 190000 | D40: 0 | E40: 0 | F40: 650000 | G40: 0 | H40: 0 | I40: 0 | J40: 1100000 | K40: 0 | L40: 0 | M40: 0 | N40: 0 | O40: 450000 | P40: =SUM(D40:O40) -> 2200000 | Q40: =C40*Старт!$D$22 -> 2280000 | R40: =Q40-P40 -> 80000 | S40: =IF(Q40=0,0,P40/Q40) -> 0.96491228
B41: Развлечения | C41: 40000 | D41: 45000 | E41: 51000 | F41: 29000 | G41: 43000 | H41: 40000 | I41: 46000 | J41: 36000 | K41: 52000 | L41: 30000 | M41: 41000 | N41: 46000 | O41: 50000 | P41: =SUM(D41:O41) -> 509000 | Q41: =C41*Старт!$D$22 -> 480000 | R41: =Q41-P41 -> -29000 | S41: =IF(Q41=0,0,P41/Q41) -> 1.0604167
B42: Хобби | C42: 25000 | D42: 29000 | E42: 28000 | F42: 29000 | G42: 31000 | H42: 23000 | I42: 28000 | J42: 31000 | K42: 31000 | L42: 24000 | M42: 29000 | N42: 30000 | O42: 26000 | P42: =SUM(D42:O42) -> 339000 | Q42: =C42*Старт!$D$22 -> 300000 | R42: =Q42-P42 -> -39000 | S42: =IF(Q42=0,0,P42/Q42) -> 1.13
B43: ПОДАРКИ И БЛАГОТВОРИТЕЛЬНОСТЬ | C43: =SUM(C44:C46) -> 150000 | D43: =SUM(D44:D46) -> 110000 | E43: =SUM(E44:E46) -> 122000 | F43: =SUM(F44:F46) -> 203000 | G43: =SUM(G44:G46) -> 122000 | H43: =SUM(H44:H46) -> 83000 | I43: =SUM(I44:I46) -> 253000 | J43: =SUM(J44:J46) -> 118000 | ... P43: =SUM(P44:P46) -> 1885000 | Q43: =C43*Старт!$D$22 -> 1800000 | R43: =Q43-P43 -> -85000 | S43: =IF(Q43=0,0,P43/Q43) -> 1.0472222
...

Sheet Капитал
B1: BUSINESS SURGERY · Личный финансовый план | Q1: =IF(Старт!$D$15="","",Старт!$D$15&" · ")&Старт!$D$16&" год" -> Ваше имя · 2026 год
B3: Капитал
B4: ДДС активов: остатки на конец каждого месяца. Валютные строки вводите в $, пересчёт в тенге по курсу месяца
B7: Актив или долг | C7: Валюта | D7: Январь | E7: Февраль | F7: Март | G7: Апрель | H7: Май | I7: Июнь | J7: Июль | K7: Август | L7: Сентябрь | M7: Октябрь | N7: Ноябрь | O7: Декабрь | P7: Изм. с января | Q7: Доля в активах
B8: Курс USD на конец месяца | C8: ₸/$ | D8: =Старт!$D$17 -> 505 | E8: =Старт!$D$17 -> 505 | F8: =Старт!$D$17 -> 505 | G8: =Старт!$D$17 -> 505 | H8: =Старт!$D$17 -> 505 | I8: =Старт!$D$17 -> 505 | J8: =Старт!$D$17 -> 505 | K8: =Старт!$D$17 -> 505 | ... O8: =Старт!$D$17 -> 505
B9: ДЕНЬГИ | D9: =SUMPRODUCT(D10:D14*(($C10:$C14="USD")*(D$8-1)+1)) -> 12019000 | E9: =SUMPRODUCT(E10:E14*(($C10:$C14="USD")*(E$8-1)+1)) -> 12846000 | F9: =SUMPRODUCT(F10:F14*(($C10:$C14="USD")*(F$8-1)+1)) -> 13852000 | G9: =SUMPRODUCT(G10:G14*(($C10:$C14="USD")*(G$8-1)+1)) -> 15452000 | H9: =SUMPRODUCT(H10:H14*(($C10:$C14="USD")*(H$8-1)+1)) -> 15911000 | I9: =SUMPRODUCT(I10:I14*(($C10:$C14="USD")*(I$8-1)+1)) -> 16171000 | J9: =SUMPRODUCT(J10:J14*(($C10:$C14="USD")*(J$8-1)+1)) -> 16314000 | K9: =SUMPRODUCT(K10:K14*(($C10:$C14="USD")*(K$8-1)+1)) -> 16638000 | ... O9: =SUMPRODUCT(O10:O14*(($C10:$C14="USD")*(O$8-1)+1)) -> 20340000 | P9: =O9-D9 -> 8321000 | Q9: =IF(O33=0,0,O9/O33) -> 0.10375698
B10: Наличные | C10: ₸ | D10: 350000 | E10: 350000 | F10: 350000 | G10: 350000 | H10: 350000 | I10: 350000 | J10: 350000 | K10: 350000 | L10: 350000 | M10: 350000 | N10: 350000 | O10: 350000 | P10: =O10-D10 -> 0
B11: Наличные | C11: USD | D11: 3000 | E11: 3000 | F11: 3000 | G11: 3000 | H11: 3000 | I11: 3000 | J11: 2000 | K11: 2000 | L11: 2000 | M11: 2000 | N11: 2000 | O11: 2000 | P11: =O11-D11 -> -1000
B12: Текущие счета и карты | C12: ₸ | D12: 1104000 | E12: 1255000 | F12: 1499000 | G12: 1569000 | H12: 1547000 | I12: 1225000 | J12: 1354000 | K12: 1181000 | L12: 1064000 | M12: 1298000 | N12: 1519000 | O12: 1527000 | P12: =O12-D12 -> 423000
B13: Депозиты | C13: ₸ | D13: 4000000 | E13: 4676000 | F13: 5438000 | G13: 5958000 | H13: 6439000 | I13: 7021000 | J13: 7540000 | K13: 8037000 | L13: 8606000 | M13: 9251000 | N13: 9849000 | O13: 10383000 | P13: =O13-D13 -> 6383000
B14: Депозиты | C14: USD | D14: 10000 | E14: 10000 | F14: 10000 | G14: 12000 | H14: 12000 | I14: 12000 | J14: 12000 | K14: 12000 | L14: 14000 | M14: 14000 | N14: 14000 | O14: 14000 | P14: =O14-D14 -> 4000
B15: ИНВЕСТИЦИИ | D15: =SUMPRODUCT(D16:D19*(($C16:$C19="USD")*(D$8-1)+1)) -> 20320000 | E15: =SUMPRODUCT(E16:E19*(($C16:$C19="USD")*(E$8-1)+1)) -> 20910000 | F15: =SUMPRODUCT(F16:F19*(($C16:$C19="USD")*(F$8-1)+1)) -> 21500000 | G15: =SUMPRODUCT(G16:G19*(($C16:$C19="USD")*(G$8-1)+1)) -> 21585000 | H15: =SUMPRODUCT(H16:H19*(($C16:$C19="USD")*(H$8-1)+1)) -> 22175000 | I15: =SUMPRODUCT(I16:I19*(($C16:$C19="USD")*(I$8-1)+1)) -> 24265000 | J15: =SUMPRODUCT(J16:J19*(($C16:$C19="USD")*(J$8-1)+1)) -> 24350000 | K15: =SUMPRODUCT(K16:K19*(($C16:$C19="USD")*(K$8-1)+1)) -> 24940000 | ... O15: =SUMPRODUCT(O16:O19*(($C16:$C19="USD")*(O$8-1)+1)) -> 26795000 | P15: =O15-D15 -> 6475000 | Q15: =IF(O33=0,0,O15/O33) -> 0.13668478
B16: Акции и ETF | C16: USD | D16: 24000 | E16: 25000 | F16: 26000 | G16: 26000 | H16: 27000 | I16: 28000 | J16: 28000 | K16: 29000 | L16: 30000 | M16: 31000 | N16: 32000 | O16: 32000 | P16: =O16-D16 -> 8000
B17: Облигации | C17: ₸ | D17: 2000000 | E17: 2000000 | F17: 2000000 | G17: 2000000 | H17: 2000000 | I17: 3500000 | J17: 3500000 | K17: 3500000 | L17: 3500000 | M17: 3500000 | N17: 3500000 | O17: 3500000 | P17: =O17-D17 -> 1500000
B18: Пенсионные накопления (ЕНПФ) | C18: ₸ | D18: 6200000 | E18: 6285000 | F18: 6370000 | G18: 6455000 | H18: 6540000 | I18: 6625000 | J18: 6710000 | K18: 6795000 | L18: 6880000 | M18: 6965000 | N18: 7050000 | O18: 7135000 | P18: =O18-D18 -> 935000
B19: Прочие инвестиции | C19: ₸ | D19: 0 | E19: 0 | F19: 0 | G19: 0 | H19: 0 | I19: 0 | J19: 0 | K19: 0 | L19: 0 | M19: 0 | N19: 0 | O19: 0 | P19: =O19-D19 -> 0
B20: БИЗНЕС | D20: =SUMPRODUCT(D21:D22*(($C21:$C22="USD")*(D$8-1)+1)) -> 63000000 | E20: =SUMPRODUCT(E21:E22*(($C21:$C22="USD")*(E$8-1)+1)) -> 63000000 | F20: =SUMPRODUCT(F21:F22*(($C21:$C22="USD")*(F$8-1)+1)) -> 63000000 | G20: =SUMPRODUCT(G21:G22*(($C21:$C22="USD")*(G$8-1)+1)) -> 66000000 | H20: =SUMPRODUCT(H21:H22*(($C21:$C22="USD")*(H$8-1)+1)) -> 65000000 | I20: =SUMPRODUCT(I21:I22*(($C21:$C22="USD")*(I$8-1)+1)) -> 65000000 | J20: =SUMPRODUCT(J21:J22*(($C21:$C22="USD")*(J$8-1)+1)) -> 67000000 | K20: =SUMPRODUCT(K21:K22*(($C21:$C22="USD")*(K$8-1)+1)) -> 67000000 | ... O20: =SUMPRODUCT(O21:O22*(($C21:$C22="USD")*(O$8-1)+1)) -> 69000000 | P20: =O20-D20 -> 6000000 | Q20: =IF(O33=0,0,O20/O33) -> 0.35197796
B21: Доля в бизнесе (оценка) | C21: ₸ | D21: 60000000 | E21: 60000000 | F21: 60000000 | G21: 63000000 | H21: 63000000 | I21: 63000000 | J21: 65000000 | K21: 65000000 | L21: 65000000 | M21: 68000000 | N21: 68000000 | O21: 68000000 | P21: =O21-D21 -> 8000000
B22: Займы, выданные бизнесу | C22: ₸ | D22: 3000000 | E22: 3000000 | F22: 3000000 | G22: 3000000 | H22: 2000000 | I22: 2000000 | J22: 2000000 | K22: 2000000 | L22: 1000000 | M22: 1000000 | N22: 1000000 | O22: 1000000 | P22: =O22-D22 -> -2000000
B23: НЕДВИЖИМОСТЬ И ИМУЩЕСТВО | D23: =SUMPRODUCT(D24:D26*(($C24:$C26="USD")*(D$8-1)+1)) -> 79000000 | E23: =SUMPRODUCT(E24:E26*(($C24:$C26="USD")*(E$8-1)+1)) -> 78900000 | F23: =SUMPRODUCT(F24:F26*(($C24:$C26="USD")*(F$8-1)+1)) -> 78800000 | G23: =SUMPRODUCT(G24:G26*(($C24:$C26="USD")*(G$8-1)+1)) -> 78700000 | H23: =SUMPRODUCT(H24:H26*(($C24:$C26="USD")*(H$8-1)+1)) -> 78600000 | I23: =SUMPRODUCT(I24:I26*(($C24:$C26="USD")*(I$8-1)+1)) -> 78500000 | J23: =SUMPRODUCT(J24:J26*(($C24:$C26="USD")*(J$8-1)+1)) -> 80400000 | K23: =SUMPRODUCT(K24:K26*(($C24:$C26="USD")*(K$8-1)+1)) -> 80300000 | ... O23: =SUMPRODUCT(O24:O26*(($C24:$C26="USD")*(O$8-1)+1)) -> 79900000 | P23: =O23-D23 -> 900000 | Q23: =IF(O33=0,0,O23/O33) -> 0.40758028
B24: Квартира, дом | C24: ₸ | D24: 65000000 | E24: 65000000 | F24: 65000000 | G24: 65000000 | H24: 65000000 | I24: 65000000 | J24: 67000000 | K24: 67000000 | L24: 67000000 | M24: 67000000 | N24: 67000000 | O24: 67000000 | P24: =O24-D24 -> 2000000
B25: Коммерческая недвижимость | C25: ₸ | D25: 0 | E25: 0 | F25: 0 | G25: 0 | H25: 0 | I25: 0 | J25: 0 | K25: 0 | L25: 0 | M25: 0 | N25: 0 | O25: 0 | P25: =O25-D25 -> 0
B26: Автомобиль | C26: ₸ | D26: 14000000 | E26: 13900000 | F26: 13800000 | G26: 13700000 | H26: 13600000 | I26: 13500000 | J26: 13400000 | K26: 13300000 | L26: 13200000 | M26: 13100000 | N26: 13000000 | O26: 12900000 | P26: =O26-D26 -> -1100000
B27: ДОЛГИ И РАССРОЧКИ | D27: =SUMPRODUCT(D28:D32*(($C28:$C32="USD")*(D$8-1)+1)) -> 31040000 | E27: =SUMPRODUCT(E28:E32*(($C28:$C32="USD")*(E$8-1)+1)) -> 30460000 | F27: =SUMPRODUCT(F28:F32*(($C28:$C32="USD")*(F$8-1)+1)) -> 29880000 | G27: =SUMPRODUCT(G28:G32*(($C28:$C32="USD")*(G$8-1)+1)) -> 29300000 | H27: =SUMPRODUCT(H28:H32*(($C28:$C32="USD")*(H$8-1)+1)) -> 28720000 | I27: =SUMPRODUCT(I28:I32*(($C28:$C32="USD")*(I$8-1)+1)) -> 28140000 | J27: =SUMPRODUCT(J28:J32*(($C28:$C32="USD")*(J$8-1)+1)) -> 27710000 | K27: =SUMPRODUCT(K28:K32*(($C28:$C32="USD")*(K$8-1)+1)) -> 26980000 | ... O27: =SUMPRODUCT(O28:O32*(($C28:$C32="USD")*(O$8-1)+1)) -> 24780000 | P27: =O27-D27 -> -6260000 | Q27: =IF(O33=0,0,O27/O33) -> 0.126406
B28: Ипотека, остаток | C28: ₸ | D28: 25800000 | E28: 25500000 | F28: 25200000 | G28: 24900000 | H28: 24600000 | I28: 24300000 | J28: 24000000 | K28: 23700000 | L28: 23400000 | M28: 23100000 | N28: 22800000 | O28: 22500000 | P28: =O28-D28 -> -3300000
B29: Автокредит, остаток | C29: ₸ | D29: 4140000 | E29: 3960000 | F29: 3780000 | G29: 3600000 | H29: 3420000 | I29: 3240000 | J29: 3060000 | K29: 2880000 | L29: 2700000 | M29: 2520000 | N29: 2340000 | O29: 2160000 | P29: =O29-D29 -> -1980000
B30: Рассрочки, остаток | C30: ₸ | D30: 1100000 | E30: 1000000 | F30: 900000 | G30: 800000 | H30: 700000 | I30: 600000 | J30: 500000 | K30: 400000 | L30: 300000 | M30: 240000 | N30: 180000 | O30: 120000 | P30: =O30-D30 -> -980000
B31: Кредитные карты | C31: ₸ | D31: 0 | E31: 0 | F31: 0 | G31: 0 | H31: 0 | I31: 0 | J31: 150000 | K31: 0 | L31: 0 | M31: 0 | N31: 0 | O31: 0 | P31: =O31-D31 -> 0
B32: Личные долги | C32: ₸ | D32: 0 | E32: 0 | F32: 0 | G32: 0 | H32: 0 | I32: 0 | J32: 0 | K32: 0 | L32: 0 | M32: 0 | N32: 0 | O32: 0 | P32: =O32-D32 -> 0
B33: ИТОГО АКТИВЫ | D33: =D9+D15+D20+D23 -> 174339000 | E33: =E9+E15+E20+E23 -> 175656000 | F33: =F9+F15+F20+F23 -> 177152000 | G33: =G9+G15+G20+G23 -> 181737000 | H33: =H9+H15+H20+H23 -> 181686000 | I33: =I9+I15+I20+I23 -> 183936000 | J33: =J9+J15+J20+J23 -> 188064000 | K33: =K9+K15+K20+K23 -> 188878000 | ... P33: =P9+P15+P20+P23 -> 21696000
B34: ИТОГО ДОЛГИ | D34: =D27 -> 31040000 | E34: =E27 -> 30460000 | F34: =F27 -> 29880000 | G34: =G27 -> 29300000 | H34: =H27 -> 28720000 | I34: =I27 -> 28140000 | J34: =J27 -> 27710000 | K34: =K27 -> 26980000 | ... P34: =P27 -> -6260000
B35: ЧИСТЫЙ КАПИТАЛ | D35: =D33-D34 -> 143299000 | E35: =E33-E34 -> 145196000 | F35: =F33-F34 -> 147272000 | G35: =G33-G34 -> 152437000 | H35: =H33-H34 -> 152966000 | I35: =I33-I34 -> 155796000 | J35: =J33-J34 -> 160354000 | K35: =K33-K34 -> 161898000 | ... P35: =P33-P34 -> 27956000
B36: Изменение за месяц | D36: 0 | E36: =E35-D35 -> 1897000 | F36: =F35-E35 -> 2076000 | G36: =G35-F35 -> 5165000 | H36: =H35-G35 -> 529000 | I36: =I35-H35 -> 2830000 | J36: =J35-I35 -> 4558000 | K36: =K35-J35 -> 1544000 | L36: =L35-K35 -> 1532000 | ... O36: =O35-N35 -> 1067000
B37: Подушка: деньги / средний расход | D37: =IF(Год!$E$21=0,0,D9/Год!$E$21) -> 5.4464711 | E37: =IF(Год!$E$21=0,0,E9/Год!$E$21) -> 5.8212303 | F37: =IF(Год!$E$21=0,0,F9/Год!$E$21) -> 6.2771043 | G37: =IF(Год!$E$21=0,0,G9/Год!$E$21) -> 7.0021525 | H37: =IF(Год!$E$21=0,0,H9/Год!$E$21) -> 7.2101507 | I37: =IF(Год!$E$21=0,0,I9/Год!$E$21) -> 7.327971 | J37: =IF(Год!$E$21=0,0,J9/Год!$E$21) -> 7.3927722 | K37: =IF(Год!$E$21=0,0,K9/Год!$E$21) -> 7.5395944 | ... O37: =IF(Год!$E$21=0,0,O9/Год!$E$21) -> 9.2171746
B38: Долги к активам | D38: =IF(D33=0,0,D34/D33) -> 0.17804393 | E38: =IF(E33=0,0,E34/E33) -> 0.17340711 | F38: =IF(F33=0,0,F34/F33) -> 0.16866871 | G38: =IF(G33=0,0,G34/G33) -> 0.16122199 | H38: =IF(H33=0,0,H34/H33) -> 0.15807492 | I38: =IF(I33=0,0,I34/I33) -> 0.152988 | J38: =IF(J33=0,0,J34/J33) -> 0.14734346 | K38: =IF(K33=0,0,K34/K33) -> 0.14284353 | ... O38: =IF(O33=0,0,O34/O33) -> 0.126406
B40: КАЛЬКУЛЯТОР КРЕДИТОВ И РАССРОЧЕК
B41: Сколько уже выплачено и сколько осталось. Платёж считается равными частями: сумма к выплате с процентами / срок.
B42: Кредит или рассрочка | C42: Срок, мес | D42: Сумма к выплате | E42: Платёж в мес | F42: Выплачено мес | G42: Осталось мес | H42: Выплачено | I42: Остаток долга | J42: Прогресс
B43: Ипотека | C43: 120 | D43: 36000000 | E43: =IF(OR(C43="",C43=0),0,D43/C43) -> 300000 | F43: 34 | G43: =IF(C43="",0,MAX(0,C43-F43)) -> 86 | H43: =E43*MIN(F43,C43) -> 10200000 | I43: =MAX(0,D43-H43) -> 25800000 | J43: =IF(N(D43)=0,0,H43/D43) -> 0.28333333
B44: Автокредит | C44: 48 | D44: 8640000 | E44: =IF(OR(C44="",C44=0),0,D44/C44) -> 180000 | F44: 27 | G44: =IF(C44="",0,MAX(0,C44-F44)) -> 21 | H44: =E44*MIN(F44,C44) -> 4860000 | I44: =MAX(0,D44-H44) -> 3780000 | J44: =IF(N(D44)=0,0,H44/D44) -> 0.5625
...

Sheet Цели
B1: BUSINESS SURGERY · Личный финансовый план | M1: =IF(Старт!$D$15="","",Старт!$D$15&" · ")&Старт!$D$16&" год" -> Ваше имя · 2026 год
B3: Цели
B4: Финансовые цели: сколько нужно, к какому сроку и сколько откладывать в месяц
B7: № | C7: Цель | D7: Категория | E7: Сумма цели | F7: Срок | G7: Накоплено | H7: Осталось | I7: Месяцев до срока | J7: Нужно в месяц | K7: Прогресс | L7: Шкала | M7: Статус
B8: 1 | C8: Финансовая подушка | D8: Подушка безопасности | E8: =ROUND(Старт!$D$19*Год!$E$21,-4) -> 13240000 | F8: 46477 | G8: =INDEX(Капитал!$D$9:$O$9,Старт!$D$22) -> 20340000 | H8: =IF(N(E8)=0,"",MAX(0,E8-G8)) -> 0 | I8: =IF(F8="","",MAX(0,(YEAR(F8)-YEAR(Старт!$D$21))*12+MONTH(F8)-MONTH(Старт!$D$21))) -> 5 | J8: =IF(N(E8)=0,"",IF(H8=0,0,IF(N(I8)=0,H8,H8/I8))) -> 0 | K8: =IF(N(E8)=0,"",MIN(1,G8/E8)) -> 1 | L8: =IF(K8="","",REPT("■",ROUND(K8*10,0))&REPT("□",10-ROUND(K8*10,0))) -> ■■■■■■■■■■ | M8: =IF(N(E8)=0,"",IF(G8>=E8,"Достигнута",IF(N(I8)=0,"Срок прошёл","В процессе"))) -> Достигнута
B9: 2 | C9: Первый взнос за коммерческое помещение | D9: Недвижимость | E9: 25000000 | F9: 47118 | G9: 8500000 | H9: =IF(N(E9)=0,"",MAX(0,E9-G9)) -> 16500000 | I9: =IF(F9="","",MAX(0,(YEAR(F9)-YEAR(Старт!$D$21))*12+MONTH(F9)-MONTH(Старт!$D$21))) -> 26 | J9: =IF(N(E9)=0,"",IF(H9=0,0,IF(N(I9)=0,H9,H9/I9))) -> 634615.38 | K9: =IF(N(E9)=0,"",MIN(1,G9/E9)) -> 0.34 | L9: =IF(K9="","",REPT("■",ROUND(K9*10,0))&REPT("□",10-ROUND(K9*10,0))) -> ■■■□□□□□□□ | M9: =IF(N(E9)=0,"",IF(G9>=E9,"Достигнута",IF(N(I9)=0,"Срок прошёл","В процессе"))) -> В процессе
B10: 3 | C10: Образование детей | D10: Образование | E10: 15000000 | F10: 48457 | G10: 3200000 | H10: =IF(N(E10)=0,"",MAX(0,E10-G10)) -> 11800000 | I10: =IF(F10="","",MAX(0,(YEAR(F10)-YEAR(Старт!$D$21))*12+MONTH(F10)-MONTH(Старт!$D$21))) -> 70 | J10: =IF(N(E10)=0,"",IF(H10=0,0,IF(N(I10)=0,H10,H10/I10))) -> 168571.43 | K10: =IF(N(E10)=0,"",MIN(1,G10/E10)) -> 0.21333333 | L10: =IF(K10="","",REPT("■",ROUND(K10*10,0))&REPT("□",10-ROUND(K10*10,0))) -> ■■□□□□□□□□ | M10: =IF(N(E10)=0,"",IF(G10>=E10,"Достигнута",IF(N(I10)=0,"Срок прошёл","В процессе"))) -> В процессе
B11: 4 | C11: Семейное путешествие | D11: Путешествие | E11: 3500000 | F11: 46568 | G11: 1400000 | H11: =IF(N(E11)=0,"",MAX(0,E11-G11)) -> 2100000 | I11: =IF(F11="","",MAX(0,(YEAR(F11)-YEAR(Старт!$D$21))*12+MONTH(F11)-MONTH(Старт!$D$21))) -> 8 | J11: =IF(N(E11)=0,"",IF(H11=0,0,IF(N(I11)=0,H11,H11/I11))) -> 262500 | K11: =IF(N(E11)=0,"",MIN(1,G11/E11)) -> 0.4 | L11: =IF(K11="","",REPT("■",ROUND(K11*10,0))&REPT("□",10-ROUND(K11*10,0))) -> ■■■■□□□□□□ | M11: =IF(N(E11)=0,"",IF(G11>=E11,"Достигнута",IF(N(I11)=0,"Срок прошёл","В процессе"))) -> В процессе
B12: 5 | C12: Новый автомобиль | D12: Автомобиль | E12: 22000000 | F12: 47299 | G12: 4000000 | H12: =IF(N(E12)=0,"",MAX(0,E12-G12)) -> 18000000 | I12: =IF(F12="","",MAX(0,(YEAR(F12)-YEAR(Старт!$D$21))*12+MONTH(F12)-MONTH(Старт!$D$21))) -> 32 | J12: =IF(N(E12)=0,"",IF(H12=0,0,IF(N(I12)=0,H12,H12/I12))) -> 562500 | K12: =IF(N(E12)=0,"",MIN(1,G12/E12)) -> 0.18181818 | L12: =IF(K12="","",REPT("■",ROUND(K12*10,0))&REPT("□",10-ROUND(K12*10,0))) -> ■■□□□□□□□□ | M12: =IF(N(E12)=0,"",IF(G12>=E12,"Достигнута",IF(N(I12)=0,"Срок прошёл","В процессе"))) -> В процессе
B13: 6 | C13: Капитал на пассивный доход | D13: Капитал и пенсия | E13: 300000000 | F13: 51501 | G13: 21000000 | H13: =IF(N(E13)=0,"",MAX(0,E13-G13)) -> 279000000 | I13: =IF(F13="","",MAX(0,(YEAR(F13)-YEAR(Старт!$D$21))*12+MONTH(F13)-MONTH(Старт!$D$21))) -> 170 | J13: =IF(N(E13)=0,"",IF(H13=0,0,IF(N(I13)=0,H13,H13/I13))) -> 1641176.5 | K13: =IF(N(E13)=0,"",MIN(1,G13/E13)) -> 0.07 | L13: =IF(K13="","",REPT("■",ROUND(K13*10,0))&REPT("□",10-ROUND(K13*10,0))) -> ■□□□□□□□□□ | M13: =IF(N(E13)=0,"",IF(G13>=E13,"Достигнута",IF(N(I13)=0,"Срок прошёл","В процессе"))) -> В процессе
B14: 7 | H14: =IF(N(E14)=0,"",MAX(0,E14-G14)) | I14: =IF(F14="","",MAX(0,(YEAR(F14)-YEAR(Старт!$D$21))*12+MONTH(F14)-MONTH(Старт!$D$21))) | J14: =IF(N(E14)=0,"",IF(H14=0,0,IF(N(I14)=0,H14,H14/I14))) | K14: =IF(N(E14)=0,"",MIN(1,G14/E14)) | L14: =IF(K14="","",REPT("■",ROUND(K14*10,0))&REPT("□",10-ROUND(K14*10,0))) | M14: =IF(N(E14)=0,"",IF(G14>=E14,"Достигнута",IF(N(I14)=0,"Срок прошёл","В процессе")))
B15: 8 | H15: =IF(N(E15)=0,"",MAX(0,E15-G15)) | I15: =IF(F15="","",MAX(0,(YEAR(F15)-YEAR(Старт!$D$21))*12+MONTH(F15)-MONTH(Старт!$D$21))) | J15: =IF(N(E15)=0,"",IF(H15=0,0,IF(N(I15)=0,H15,H15/I15))) | K15: =IF(N(E15)=0,"",MIN(1,G15/E15)) | L15: =IF(K15="","",REPT("■",ROUND(K15*10,0))&REPT("□",10-ROUND(K15*10,0))) | M15: =IF(N(E15)=0,"",IF(G15>=E15,"Достигнута",IF(N(I15)=0,"Срок прошёл","В процессе")))
B16: 9 | H16: =IF(N(E16)=0,"",MAX(0,E16-G16)) | I16: =IF(F16="","",MAX(0,(YEAR(F16)-YEAR(Старт!$D$21))*12+MONTH(F16)-MONTH(Старт!$D$21))) | J16: =IF(N(E16)=0,"",IF(H16=0,0,IF(N(I16)=0,H16,H16/I16))) | K16: =IF(N(E16)=0,"",MIN(1,G16/E16)) | L16: =IF(K16="","",REPT("■",ROUND(K16*10,0))&REPT("□",10-ROUND(K16*10,0))) | M16: =IF(N(E16)=0,"",IF(G16>=E16,"Достигнута",IF(N(I16)=0,"Срок прошёл","В процессе")))
B17: 10 | H17: =IF(N(E17)=0,"",MAX(0,E17-G17)) | I17: =IF(F17="","",MAX(0,(YEAR(F17)-YEAR(Старт!$D$21))*12+MONTH(F17)-MONTH(Старт!$D$21))) | J17: =IF(N(E17)=0,"",IF(H17=0,0,IF(N(I17)=0,H17,H17/I17))) | K17: =IF(N(E17)=0,"",MIN(1,G17/E17)) | L17: =IF(K17="","",REPT("■",ROUND(K17*10,0))&REPT("□",10-ROUND(K17*10,0))) | M17: =IF(N(E17)=0,"",IF(G17>=E17,"Достигнута",IF(N(I17)=0,"Срок прошёл","В процессе")))
C18: ИТОГО ПО ЦЕЛЯМ | E18: =SUM(E8:E17) -> 378740000 | G18: =SUM(G8:G17) -> 58440000 | H18: =SUM(H8:H17) -> 327400000 | J18: =SUM(J8:J17) -> 3269363.3 | K18: =IF(E18=0,0,G18/E18) -> 0.1543011
C20: ХВАТАЕТ ЛИ СБЕРЕЖЕНИЙ НА ЦЕЛИ
C21: Нужно откладывать на все цели в месяц | E21: =J18 -> 3269363.3 | G21: Если покрытие меньше 100%: сдвиньте сроки, уменьшите суммы или увеличьте норму сбережений. Цели расставьте по приоритету: сначала подушка, потом остальное.
C22: Ваши средние сбережения в месяц | E22: =Год!$H$21 -> 1106500
C23: Покрытие целей сбережениями | E23: =IF(J18=0,0,Год!$H$21/J18) -> 0.33844511
C24: Разница в месяц | E24: =Год!$H$21-J18 -> -2162863.3
B26: © Business Surgery · bxclub.kz | M26: Шаблон для резидентов клуба

Sheet Правила
B1: BUSINESS SURGERY · Личный финансовый план | J1: =IF(Старт!$D$15="","",Старт!$D$15&" · ")&Старт!$D$16&" год" -> Ваше имя · 2026 год
B3: Правила
B4: Короткие правила личных финансов для собственника бизнеса. Проверено на практике, без теории
B7: 01 | C7: Разделите деньги бизнеса и личные | D7: Отдельные счета и карты. Бизнес не оплачивает личные покупки, вы не кредитуете бизнес из семейного бюджета без договора займа. Деньги из кассы себе не берутся.
B8: 02 | C8: Платите себе зарплату собственника | D8: Фиксированная сумма в один и тот же день месяца, независимо от выручки. Сверху, раз в квартал, дивиденды из накопленной прибыли.
B9: 03 | C9: Profit First: сначала прибыль | D9: С каждого поступления выручки сразу распределяйте деньги по счетам: прибыль, зарплата собственника, налоги, операционные расходы. Расходы бизнеса живут на остатке, а не наоборот. Калькулятор ниже.
B10: 04 | C10: Сначала заплатите себе | D10: В день получения личного дохода переводите 20-30% на сберегательный счёт. Тратится то, что осталось. Норма сбережений на Дашборде должна быть не ниже цели со Старта.
B11: 05 | C11: Подушка безопасности: 6 месяцев | D11: Шесть месяцев личных расходов на депозите с быстрым снятием, для предпринимателя лучше 6-12. Подушку не инвестируют и не дают в долг, в том числе своему бизнесу.
B12: 06 | C12: Инвестируйте регулярно и не только в свой бизнес | D12: От 10% дохода ежемесячно в инструменты вне вашей компании: депозиты, облигации, акции и ETF, недвижимость. Часть капитала держите в валюте. Если бизнес даёт больше 80% дохода, это риск.
B13: 07 | C13: Кредиты под контролем | D13: Платежи по личным кредитам не больше 30% личного дохода. Не берите потребительские кредиты на нужды бизнеса. Рассрочка без переплаты только если сумма уже есть на счету.
B14: 08 | C14: Бюджет на месяц вперёд, факт каждую неделю | D14: 15 минут в неделю: внесите факт расходов из банковских выписок. Раз в месяц обновите капитал, раз в квартал пересмотрите цели и бюджет.
B15: 09 | C15: Правило 72 часов для крупных покупок | D15: Любая незапланированная покупка дороже 5% месячного дохода ждёт трое суток. Половина желаний за это время исчезает.
B16: 10 | C16: Считайте капитал, а не доход | D16: Главная цифра плана: рост чистого капитала за год. Высокий доход без роста капитала означает, что деньги проходят мимо вас.
B18: ПРОВЕРКА ПО ВАШИМ ЦИФРАМ | H18: КАЛЬКУЛЯТОР PROFIT FIRST
C19: Показатель | D19: Сейчас | E19: Ориентир | F19: Статус | H19: Счёт | I19: Доля | J19: Сумма
B20: 01 | C20: Норма сбережений за год | D20: =Год!$I$20 -> 0.33396212 | E20: =Старт!$D$18 -> 0.25 | F20: =IF(D20>=E20,"В норме","Ниже цели") -> В норме | H20: Поступление выручки | J20: 5000000
B21: 02 | C21: Подушка безопасности | D21: =INDEX(Капитал!$D$37:$O$37,Старт!$D$22) -> 9.2171746 | E21: =Старт!$D$19 -> 6 | F21: =IF(D21>=E21,"В норме","Мало") -> В норме | H21: Прибыль | I21: 0.05 | J21: =$J$20*I21 -> 250000
B22: 03 | C22: Кредитная нагрузка | D22: =IF(Год!$C$20=0,0,Расходы!$P$47/Год!$C$20) -> 0.085263714 | E22: =Старт!$D$20 -> 0.3 | F22: =IF(D22<=E22,"В норме","Высокая") -> В норме | H22: Зарплата собственника | I22: 0.5 | J22: =$J$20*I22 -> 2500000
B23: 04 | C23: Доля бизнеса в доходе | D23: =IF(Год!$C$20=0,0,Год!$D$20/Год!$C$20) -> 0.60527176 | E23: 0.8 | F23: =IF(D23<=E23,"В норме","Мало диверсификации") -> В норме | H23: Налоги | I23: 0.15 | J23: =$J$20*I23 -> 750000
B24: 05 | C24: Рост чистого капитала с января | D24: =Капитал!$P$35 -> 27956000 | E24: 0 | F24: =IF(D24>E24,"Растёт","Не растёт") -> Растёт | H24: Операционные расходы | I24: 0.3 | J24: =$J$20*I24 -> 1500000
H25: Проверка: сумма долей | I25: =SUM(I21:I24) -> 1 | J25: =SUM(J21:J24) -> 5000000
H26: Ориентир для малого бизнеса. Подберите доли
H27: под свою маржу: начните с 1-5% прибыли
H28: и повышайте раз в квартал.
B29: © Business Surgery · bxclub.kz | J29: Шаблон для резидентов клуба

Sheet Год
B1: BUSINESS SURGERY · Личный финансовый план | L1: =IF(Старт!$D$15="","",Старт!$D$15&" · ")&Старт!$D$16&" год" -> Ваше имя · 2026 год
B3: Итоги года
B4: Помесячная сводка: собирается автоматически из листов Доходы, Расходы и Капитал
B5: Месяц на Дашборде: | D5: =IFERROR(MATCH(Дашборд!$E$6,$B$8:$B$19,0),1) -> 12
B7: Месяц | C7: Доходы | D7: из них бизнес | E7: Расходы | F7: Бюджет расходов | G7: Отклонение от бюджета | H7: Сбережения | I7: Норма сбережений | J7: Чистый капитал | K7: Изменение капитала | L7: Деньги (подушка)
B8: Январь | C8: =Доходы!D25 -> 2761000 | D8: =Доходы!D8 -> 1561000 | E8: =Расходы!D55 -> 2116000 | F8: =IF(E8=0,0,Расходы!$C$55) -> 2246000 | G8: =F8-E8 -> 130000 | H8: =C8-E8 -> 645000 | I8: =IF(C8=0,0,H8/C8) -> 0.23361101 | J8: =Капитал!D35 -> 143299000 | K8: =Капитал!D36 -> 0 | L8: =Капитал!D9 -> 12019000 | N8: Янв
B9: Февраль | C9: =Доходы!E25 -> 2861000 | D9: =Доходы!E8 -> 1707000 | E9: =Расходы!E55 -> 2135000 | F9: =IF(E9=0,0,Расходы!$C$55) -> 2246000 | G9: =F9-E9 -> 111000 | H9: =C9-E9 -> 726000 | I9: =IF(C9=0,0,H9/C9) -> 0.25375743 | J9: =Капитал!E35 -> 145196000 | K9: =Капитал!E36 -> 1897000 | L9: =Капитал!E9 -> 12846000 | N9: Фев
B10: Март | C10: =Доходы!F25 -> 3508000 | D10: =Доходы!F8 -> 1963000 | E10: =Расходы!F55 -> 2688000 | F10: =IF(E10=0,0,Расходы!$C$55) -> 2246000 | G10: =F10-E10 -> -442000 | H10: =C10-E10 -> 820000 | I10: =IF(C10=0,0,H10/C10) -> 0.23375143 | J10: =Капитал!F35 -> 147272000 | K10: =Капитал!F36 -> 2076000 | L10: =Капитал!F9 -> 13852000 | N10: Мар
B11: Апрель | C11: =Доходы!G25 -> 3190000 | D11: =Доходы!G8 -> 1876000 | E11: =Расходы!G55 -> 2104000 | F11: =IF(E11=0,0,Расходы!$C$55) -> 2246000 | G11: =F11-E11 -> 142000 | H11: =C11-E11 -> 1086000 | I11: =IF(C11=0,0,H11/C11) -> 0.34043887 | J11: =Капитал!G35 -> 152437000 | K11: =Капитал!G36 -> 5165000 | L11: =Капитал!G9 -> 15452000 | N11: Апр
B12: Май | C12: =Доходы!H25 -> 3234000 | D12: =Доходы!H8 -> 2066000 | E12: =Расходы!H55 -> 1991000 | F12: =IF(E12=0,0,Расходы!$C$55) -> 2246000 | G12: =F12-E12 -> 255000 | H12: =C12-E12 -> 1243000 | I12: =IF(C12=0,0,H12/C12) -> 0.38435374 | J12: =Капитал!H35 -> 152966000 | K12: =Капитал!H36 -> 529000 | L12: =Капитал!H9 -> 15911000 | N12: Май
B13: Июнь | C13: =Доходы!I25 -> 3653000 | D13: =Доходы!I8 -> 2282000 | E13: =Расходы!I55 -> 1989000 | F13: =IF(E13=0,0,Расходы!$C$55) -> 2246000 | G13: =F13-E13 -> 257000 | H13: =C13-E13 -> 1664000 | I13: =IF(C13=0,0,H13/C13) -> 0.45551601 | J13: =Капитал!I35 -> 155796000 | K13: =Капитал!I36 -> 2830000 | L13: =Капитал!I9 -> 16171000 | N13: Июн
B14: Июль | C14: =Доходы!J25 -> 3049000 | D14: =Доходы!J8 -> 1692000 | E14: =Расходы!J55 -> 2940000 | F14: =IF(E14=0,0,Расходы!$C$55) -> 2246000 | G14: =F14-E14 -> -694000 | H14: =C14-E14 -> 109000 | I14: =IF(C14=0,0,H14/C14) -> 0.035749426 | J14: =Капитал!J35 -> 160354000 | K14: =Капитал!J36 -> 4558000 | L14: =Капитал!J9 -> 16314000 | N14: Июл
B15: Август | C15: =Доходы!K25 -> 2979000 | D15: =Доходы!K8 -> 1797000 | E15: =Расходы!K55 -> 1647000 | F15: =IF(E15=0,0,Расходы!$C$55) -> 2246000 | G15: =F15-E15 -> 599000 | H15: =C15-E15 -> 1332000 | I15: =IF(C15=0,0,H15/C15) -> 0.44712991 | J15: =Капитал!K35 -> 161898000 | K15: =Капитал!K36 -> 1544000 | L15: =Капитал!K9 -> 16638000 | N15: Авг
B16: Сентябрь | C16: =Доходы!L25 -> 3273000 | D16: =Доходы!L8 -> 1975000 | E16: =Расходы!L55 -> 2514000 | F16: =IF(E16=0,0,Расходы!$C$55) -> 2246000 | G16: =F16-E16 -> -268000 | H16: =C16-E16 -> 759000 | I16: =IF(C16=0,0,H16/C16) -> 0.23189734 | J16: =Капитал!L35 -> 163430000 | K16: =Капитал!L36 -> 1532000 | L16: =Капитал!L9 -> 18100000 | N16: Сен
B17: Октябрь | C17: =Доходы!M25 -> 3572000 | D17: =Доходы!M8 -> 2082000 | E17: =Расходы!M55 -> 1959000 | F17: =IF(E17=0,0,Расходы!$C$55) -> 2246000 | G17: =F17-E17 -> 287000 | H17: =C17-E17 -> 1613000 | I17: =IF(C17=0,0,H17/C17) -> 0.45156775 | J17: =Капитал!M35 -> 168339000 | K17: =Капитал!M36 -> 4909000 | L17: =Капитал!M9 -> 18979000 | N17: Окт
B18: Ноябрь | C18: =Доходы!N25 -> 3273000 | D18: =Доходы!N8 -> 2078000 | E18: =Расходы!N55 -> 1925000 | F18: =IF(E18=0,0,Расходы!$C$55) -> 2246000 | G18: =F18-E18 -> 321000 | H18: =C18-E18 -> 1348000 | I18: =IF(C18=0,0,H18/C18) -> 0.41185457 | J18: =Капитал!N35 -> 170188000 | K18: =Капитал!N36 -> 1849000 | L18: =Капитал!N9 -> 19798000 | N18: Ноя
B19: Декабрь | C19: =Доходы!O25 -> 4406000 | D19: =Доходы!O8 -> 2986000 | E19: =Расходы!O55 -> 2473000 | F19: =IF(E19=0,0,Расходы!$C$55) -> 2246000 | G19: =F19-E19 -> -227000 | H19: =C19-E19 -> 1933000 | I19: =IF(C19=0,0,H19/C19) -> 0.43871993 | J19: =Капитал!O35 -> 171255000 | K19: =Капитал!O36 -> 1067000 | L19: =Капитал!O9 -> 20340000 | N19: Дек
B20: ИТОГО ЗА ГОД | C20: =SUM(C8:C19) -> 39759000 | D20: =SUM(D8:D19) -> 24065000 | E20: =SUM(E8:E19) -> 26481000 | F20: =SUM(F8:F19) -> 26952000 | G20: =SUM(G8:G19) -> 471000 | H20: =SUM(H8:H19) -> 13278000 | I20: =IF(C20=0,0,H20/C20) -> 0.33396212 | J20: =INDEX(J8:J19,Старт!$D$22) -> 171255000 | K20: =J20-J8 -> 27956000 | L20: =INDEX(L8:L19,Старт!$D$22) -> 20340000
B21: В среднем в мес | C21: =C20/Старт!$D$22 -> 3313250 | D21: =D20/Старт!$D$22 -> 2005416.7 | E21: =E20/Старт!$D$22 -> 2206750 | F21: =F20/Старт!$D$22 -> 2246000 | G21: =G20/Старт!$D$22 -> 39250 | H21: =H20/Старт!$D$22 -> 1106500 | I21: =I20 -> 0.33396212 | K21: =K20/Старт!$D$22 -> 2329666.7
B24: СТРУКТУРА РАСХОДОВ ЗА ГОД | J24: СТРУКТУРА ДОХОДОВ ЗА ГОД
B25: Группа | D25: Факт | E25: Бюджет за период | F25: Отклонение | G25: Доля | H25: В среднем в мес | J25: Источник | K25: Факт | L25: Доля
B26: Жильё | D26: =Расходы!P8 -> 4622000 | E26: =Расходы!Q8 -> 4692000 | F26: =E26-D26 -> 70000 | G26: =IF($D$37=0,0,D26/$D$37) -> 0.17454024 | H26: =D26/Старт!$D$22 -> 385166.67 | J26: Бизнес-дивиденды | K26: =Доходы!P8 -> 24065000 | L26: =Доходы!R8 -> 0.60527176
B27: Еда | D27: =Расходы!P13 -> 4015000 | E27: =Расходы!Q13 -> 4020000 | F27: =E27-D27 -> 5000 | G27: =IF($D$37=0,0,D27/$D$37) -> 0.15161814 | H27: =D27/Старт!$D$22 -> 334583.33 | J27: Зарплата | K27: =Доходы!P12 -> 10330000 | L27: =Доходы!R12 -> 0.25981539
B28: Семья и дети | D28: =Расходы!P17 -> 3648000 | E28: =Расходы!Q17 -> 4020000 | F28: =E28-D28 -> 372000 | G28: =IF($D$37=0,0,D28/$D$37) -> 0.13775915 | H28: =D28/Старт!$D$22 -> 304000 | J28: Инвестиции и акции | K28: =Доходы!P15 -> 1764000 | L28: =Доходы!R15 -> 0.044367313
B29: Транспорт | D29: =Расходы!P22 -> 1303000 | E29: =Расходы!Q22 -> 1236000 | F29: =E29-D29 -> -67000 | G29: =IF($D$37=0,0,D29/$D$37) -> 0.04920509 | H29: =D29/Старт!$D$22 -> 108583.33 | J29: Аренда | K29: =Доходы!P19 -> 3360000 | L29: =Доходы!R19 -> 0.084509168
B30: Здоровье и спорт | D30: =Расходы!P27 -> 1397000 | E30: =Расходы!Q27 -> 1500000 | F30: =E30-D30 -> 103000 | G30: =IF($D$37=0,0,D30/$D$37) -> 0.052754805 | H30: =D30/Старт!$D$22 -> 116416.67 | J30: Прочее | K30: =Доходы!P22 -> 240000 | L30: =Доходы!R22 -> 0.0060363691
B31: Одежда | D31: =Расходы!P32 -> 1035000 | E31: =Расходы!Q32 -> 984000 | F31: =E31-D31 -> -51000 | G31: =IF($D$37=0,0,D31/$D$37) -> 0.039084627 | H31: =D31/Старт!$D$22 -> 86250 | J31: ИТОГО | K31: =SUM(K26:K30) -> 39759000 | L31: =SUM(L26:L30) -> 1
B32: Образование | D32: =Расходы!P35 -> 1754000 | E32: =Расходы!Q35 -> 1764000 | F32: =E32-D32 -> 10000 | G32: =IF($D$37=0,0,D32/$D$37) -> 0.066236169 | H32: =D32/Старт!$D$22 -> 146166.67
B33: Отдых | D33: =Расходы!P39 -> 3048000 | E33: =Расходы!Q39 -> 3060000 | F33: =E33-D33 -> 12000 | G33: =IF($D$37=0,0,D33/$D$37) -> 0.11510139 | H33: =D33/Старт!$D$22 -> 254000
B34: Подарки и благотворительность | D34: =Расходы!P43 -> 1885000 | E34: =Расходы!Q43 -> 1800000 | F34: =E34-D34 -> -85000 | G34: =IF($D$37=0,0,D34/$D$37) -> 0.071183112 | H34: =D34/Старт!$D$22 -> 157083.33
B35: Кредиты | D35: =Расходы!P47 -> 3390000 | E35: =Расходы!Q47 -> 3360000 | F35: =E35-D35 -> -30000 | G35: =IF($D$37=0,0,D35/$D$37) -> 0.12801631 | H35: =D35/Старт!$D$22 -> 282500
B36: Прочее | D36: =Расходы!P51 -> 384000 | E36: =Расходы!Q51 -> 516000 | F36: =E36-D36 -> 132000 | G36: =IF($D$37=0,0,D36/$D$37) -> 0.014500963 | H36: =D36/Старт!$D$22 -> 32000
B37: ИТОГО | D37: =SUM(D26:D36) -> 26481000 | E37: =SUM(E26:E36) -> 26952000 | F37: =SUM(F26:F36) -> 471000 | G37: =SUM(G26:G36) -> 1 | H37: =SUM(H26:H36) -> 2206750
B39: © Business Surgery · bxclub.kz | L39: Шаблон для резидентов клуба
